<?xml version="1.0"?>
<robot xmlns:xacro="http://www.ros.org/wiki/xacro">

    <xacro:include filename="inertial_macros.xacro"/>
    <xacro:macro name="waveshare_real" params="prefix">

        <material name="white">
            <color rgba="1 1 1 1"/>
        </material>

        <material name="blue">
            <color rgba="0.2 0.2 1 1"/>
        </material>

        <material name="orange">
            <color rgba="1 0.3 0.1 1"/>
        </material>

        <material name="red">
            <color rgba="1 0 0 1"/>
        </material>
        
        <link name="${prefix}base_link">

        </link>

        <link name="${prefix}base_footprint">
        </link>

        <joint name="${prefix}base_footprint_joint" type="fixed">
            <parent link="${prefix}base_link"/>
            <child link="${prefix}base_footprint"/>
            <origin xyz="0 0 0" rpy="0 0 0"/>
        </joint> 

        <joint name="${prefix}chassis_joint" type="fixed">
            <parent link="${prefix}base_link"/>
            <child link="${prefix}chassis_link"/>
            <origin xyz="-0.043 0.0 -0.0063"/>
        </joint>

        <link name="${prefix}chassis_link">
            <visual>
                <origin xyz="0.0915 0.0 0.02735"/>
                <geometry>
                    <box size="0.183 0.083 0.0547"/>
                </geometry>
                <material name="white"/>
            </visual>
            <collision>
                <origin xyz="0.0915 0 0.02735"/>
                <geometry>
                    <box size="0.183 0.083 0.0547"/>
                </geometry>
            </collision>
            <xacro:inertial_box mass="0.66" x="0.183" y="0.083" z="0.0547">
                <origin xyz="0.0915 0 0.02735" rpy="0 0 0"/>
            </xacro:inertial_box>
        </link>

        <link name="${prefix}rlw_link">
            <visual>
                <geometry>
                    <cylinder length="0.0425" radius="0.04"/>
                </geometry>
                <material name="blue"/>
            </visual>
            <collision>
                <geometry>
                    <cylinder radius="0.04" length="0.0425"/>
                </geometry>
            </collision>
            <xacro:inertial_cylinder mass="0.05" length="0.0425" radius="0.04">
                <origin xyz="0 0 0" rpy="0 0 0"/>
            </xacro:inertial_cylinder>
        </link>

        <joint name="${prefix}rlw_joint" type="continuous">
            <parent link="${prefix}base_link"/>
            <child link="${prefix}rlw_link"/>
            <origin xyz="0.0 0.06275 0.0" rpy="-1.5708 0 0"/>
            <axis xyz="0 0 1"/>
            <dynamics damping="0.2"/>
        </joint>

        <link name="${prefix}rrw_link">
            <visual>
                <geometry>
                    <cylinder length="0.0425" radius="0.04"/>
                </geometry>
                <material name="blue"/>
            </visual>
            <collision>
                <geometry>
                    <cylinder radius="0.04" length="0.0425"/>
                </geometry>
            </collision>
            <xacro:inertial_cylinder mass="0.05" length="0.0425" radius="0.04">
                <origin xyz="0 0 0" rpy="0 0 0"/>
            </xacro:inertial_cylinder>
        </link>

        <joint name="${prefix}rrw_joint" type="continuous">
            <parent link="${prefix}base_link"/>
            <child link="${prefix}rrw_link"/>
            <origin xyz="0.0 -0.06275 0.0" rpy="1.5708 0 0"/>
            <axis xyz="0 0 -1"/> 
            <dynamics damping="0.2"/>
        </joint>

        <link name="${prefix}flw_link">
            <visual>
                <geometry>
                    <cylinder length="0.0425" radius="0.04"/>
                </geometry>
                <material name="orange"/>
            </visual>
            <collision>
                <geometry>
                    <cylinder radius="0.04" length="0.0425"/>
                </geometry>
            </collision>
            <xacro:inertial_cylinder mass="0.05" length="0.0425" radius="0.04">
                <origin xyz="0 0 0" rpy="0 0 0"/>
            </xacro:inertial_cylinder>
        </link>

        <joint name="${prefix}flw_joint" type="continuous">
            <parent link="${prefix}base_link"/>
            <child link="${prefix}flw_link"/>
            <origin xyz="0.097 0.06275 0.0" rpy="-1.5708 0 0"/>
            <axis xyz="0 0 1"/> 
            <dynamics damping="0.2"/>
        </joint>

        <link name="${prefix}frw_link">
            <visual>
                <geometry>
                    <cylinder length="0.0425" radius="0.04"/>
                </geometry>
                <material name="orange"/>
            </visual>
            <collision>
                <geometry>
                    <cylinder radius="0.04" length="0.0425"/>
                </geometry>
            </collision>
            <xacro:inertial_cylinder mass="0.05" length="0.0425" radius="0.04">
                <origin xyz="0 0 0" rpy="0 0 0"/>
            </xacro:inertial_cylinder>
        </link>

        <joint name="${prefix}frw_joint" type="continuous">
            <parent link="${prefix}base_link"/>
            <child link="${prefix}frw_link"/>
            <origin xyz="0.097 -0.06275 0.0" rpy="1.5708 0 0"/>
            <axis xyz="0 0 -1"/> 
            <dynamics damping="0.2"/>
        </joint>
    </xacro:macro>
</robot>